<?xml version="1.0" ?>
<robot name="canine-leg-left-V4">
  <material name="black">
    <color rgba="0.0 0.0 0.0 1.0"/>
  </material>

  <material name="white">
     <color rgba="1.0 1.0 1.0 1.0"/>
  </material>

  <material name="black1">
      <color rgba="0.2 0.2 0.2 1.0"/>
  </material>

  <material name="black2">
      <color rgba="0.5 0.5 0.5 1.0"/>
  </material>
  <link name="world"/>
  <joint name="fixed" type="fixed">
    <parent link="world"/>
    <child link="base"/>
  </joint>

  <link name="base">
    <visual>
      <origin rpy="0 0 0" xyz="0 0 0.5"/>
      <geometry>
        <box size="0.025 0.025 1.0"/>
      </geometry>
      <material name="white"/>
    </visual>

    <collision>
        <origin rpy="0 0 0" xyz="0 0 0.5"/>
      <geometry>
        <box size="0.025 0.025 1.0"/>
      </geometry>
    </collision>

    <inertial>
      <mass value="10"/>
      <inertia ixx="1.0" ixy="0.0" ixz="0.0" iyy="1.0" iyz="0.0" izz="1.0"/>
    </inertial>
  </link>

  <joint name="linear_guide" type="prismatic">
    <origin rpy="0 0 0" xyz="0 -0.025 0.0"/>
    <parent link="base"/>
    <child link="hip_1"/>
    <axis xyz="0 0 1"/>
  </joint>

  <link name="hip_1">
    <visual>
      <origin rpy="0 0 1.570796" xyz="-0.12 0.040 0.0"/>
      <geometry>
        <mesh filename="base_link.STL" />
      </geometry>
      <material name="black1"/>
    </visual>

    <collision>
      <origin rpy="-1.570796 0 0" xyz="0.0 0 0.0"/>
      <geometry>
        <cylinder length="0.034" radius="0.049"/>
      </geometry>
    </collision>

    <inertial>
      <mass value="1.8833"/>
      <inertia ixx="0.001311875392" ixy="0.0" ixz="0.0" iyy="0.00226090165" iyz="0.0" izz="0.001311875392"/>
    </inertial>
  </link>

  <joint name="hip_pitch" type="revolute">
    <origin rpy="0 0 0" xyz="0 -0.090 0.0"/>
    <parent link="hip_1"/>
    <child link="hip_2"/>
    <axis xyz="0 -1 0"/>
  </joint>

  <link name="hip_2">
      <visual>
        <origin rpy="0 0 -3.141592" xyz="0.257 0.15 0.0"/>
        <geometry>
          <mesh filename="FL_thigh_1.STL" scale="0.001 0.001 0.001"/>
        </geometry>
        <material name="black1"/>
      </visual>

      <collision>
        <origin rpy="-1.570796 0 0" xyz="0.0 0 0.0"/>
        <geometry>
          <cylinder length="0.034" radius="0.049"/>
        </geometry>
      </collision>

      <inertial>
        <mass value="1.065"/>
        <inertia ixx="0.00074186125" ixy="0.0" ixz="0.0" iyy="0.0012785325" iyz="0.0" izz="0.00074186125"/>
      </inertial>
  </link>

  <joint name="hip_upper" type="fixed">
        <origin rpy="0 0 0" xyz="0 0 0"/>
        <parent link="hip_2"/>
        <child link="upper_leg"/>
  </joint>

  <link name="upper_leg">

    <collision>
      <origin rpy="0 0 0" xyz="0 0 -0.115"/>
      <geometry>
        <box size="0.03 0.02 0.23"/>
      </geometry>
    </collision>

    <inertial>
      <mass value="0.48115"/>
      <inertia ixx="0.002137107917" ixy="0.0" ixz="0.0" iyy="0.002157155833" iyz="0.0" izz="0.000052124583"/>
    </inertial>
  </link>

  <joint name="knee_pitch" type="revolute">
    <origin rpy="0 0 0" xyz="0 0 -0.23"/>
    <parent link="upper_leg"/>
    <child link="lower_leg"/>
    <axis xyz="0 -1 0"/>
  </joint>

  <link name="lower_leg">
    <visual>
      <origin rpy="-3.141592 -3.141592 0" xyz="0.257 0.145 0.23"/>
      <geometry>
        <mesh filename="FL_calf_1.STL"  scale="0.001 0.001 0.001"/>
      </geometry>
      <material name="black2"/>
    </visual>

    <collision>
      <origin rpy="0 0 0" xyz="0 0 -0.23"/>
      <geometry>
        <sphere radius="0.015"/>
      </geometry>
    </collision>

    <inertial>
      <mass value="0.4049"/>
      <inertia ixx="0.001798430833" ixy="0.0" ixz="0.0" iyy="0.001815301667" iyz="0.0" izz="0.000043864167"/>
    </inertial>
  </link>
</robot>